Workbook

Sheet ★共創(2023入) 
B1: 共創学部 卒業要件チェック表（第１面） | L1: 学生番号： | M1: =IF(入力用!C3="","",入力用!C3)
B2: （2023年度入学者用） | L2: 氏名： | M2: =IF(入力用!C4="","",入力用!C4)
L3: チェック日： | M3: =IF(入力用!C5="","",入力用!C5)
B4: Ⅰ．基幹教育科目（４８単位） | E4: □＝チェック欄（取得済みはチェック）
B5: 基幹教育セミナー（必修：１単位） | M5: 総合科目 | O5: その他(Ｄ） | Q5: その他(い）
B6: 基幹教育セミナー | G6: 1 | H6: =IF(入力用!F16="✓","✓","□") -> □ | J6: 単位 | M6: =IF(入力用!C89="","〔 〕",入力用!C89) -> 〔 〕 | N6: =IF(入力用!D89="","（ ）",入力用!D89) -> （ ） | O6: =IF(入力用!G89="","□",入力用!G89) -> □ | P6: =IF(入力用!E89="","（ ）",入力用!E89) -> （ ） | Q6: =IF(入力用!H89="","□",入力用!H89) -> □ | R6: =IF(入力用!G89="","（ ）",入力用!G89) -> （ ）
M7: =IF(入力用!C90="","〔 〕",入力用!C90) -> 〔 〕 | N7: =IF(入力用!D90="","（ ）",入力用!D90) -> （ ） | O7: =IF(入力用!G90="","□",入力用!G90) -> □ | P7: =IF(入力用!E90="","（ ）",入力用!E90) -> （ ） | Q7: =IF(入力用!H90="","□",入力用!H90) -> □ | R7: =IF(入力用!G90="","（ ）",入力用!G90) -> （ ）
B8: 課題協学科目（必修：２．５単位） | M8: =IF(入力用!C91="","〔 〕",入力用!C91) -> 〔 〕 | N8: =IF(入力用!D91="","（ ）",入力用!D91) -> （ ） | O8: =IF(入力用!G91="","□",入力用!G91) -> □ | P8: =IF(入力用!E91="","（ ）",入力用!E91) -> （ ） | Q8: =IF(入力用!H91="","□",入力用!H91) -> □ | R8: =IF(入力用!G91="","（ ）",入力用!G91) -> （ ）
B9: 課題協学科目 | G9: 2.5 | H9: =IF(入力用!F17="✓","✓","□") -> □ | J9: 単位 | M9: =IF(入力用!C92="","〔 〕",入力用!C92) -> 〔 〕 | N9: =IF(入力用!D92="","（ ）",入力用!D92) -> （ ） | O9: =IF(入力用!G92="","□",入力用!G92) -> □ | P9: =IF(入力用!E92="","（ ）",入力用!E92) -> （ ） | Q9: =IF(入力用!H92="","□",入力用!H92) -> □ | R9: =IF(入力用!G92="","（ ）",入力用!G92) -> （ ）
M10: =IF(入力用!C93="","〔 〕",入力用!C93) -> 〔 〕 | N10: =IF(入力用!D93="","（ ）",入力用!D93) -> （ ） | O10: =IF(入力用!G93="","□",入力用!G93) -> □ | P10: =IF(入力用!E93="","（ ）",入力用!E93) -> （ ） | Q10: =IF(入力用!H93="","□",入力用!H93) -> □ | R10: =IF(入力用!G93="","（ ）",入力用!G93) -> （ ）
B11: 文系ﾃﾞィｼﾌﾟﾘﾝ科目（必修：８単位），理系ﾃﾞィｼﾌﾟﾘﾝ科目（必修：８単位） | M11: =IF(入力用!C94="","〔 〕",入力用!C94) -> 〔 〕 | N11: =IF(入力用!D94="","（ ）",入力用!D94) -> （ ） | O11: =IF(入力用!G94="","□",入力用!G94) -> □ | P11: =IF(入力用!E94="","（ ）",入力用!E94) -> （ ） | Q11: =IF(入力用!H94="","□",入力用!H94) -> □ | R11: =IF(入力用!G94="","（ ）",入力用!G94) -> （ ）
B12: 文系 | C12: =IF(入力用!C19="","〔 〕",入力用!C19) -> 〔 〕 | D12: =IF(入力用!D19="","（ ）",入力用!D19) -> （ ） | E12: =IF(入力用!F19="✓","✓","□") -> □ | F12: =IF(入力用!C22="","〔 〕",入力用!C22) -> 〔 〕 | G12: =IF(入力用!D22="","（ ）",入力用!D22) -> （ ） | H12: =IF(入力用!F22="✓","✓","□") -> □ | M12: 合計 | O12: その他(Ｄ）計 | Q12: その他(い）計
C13: =IF(入力用!C20="","〔 〕",入力用!C20) -> 〔 〕 | D13: =IF(入力用!D20="","（ ）",入力用!D20) -> （ ） | E13: =IF(入力用!F20="✓","✓","□") -> □ | F13: =IF(入力用!C23="","〔 〕",入力用!C23) -> 〔 〕 | G13: =IF(入力用!D23="","（ ）",入力用!D23) -> （ ） | H13: =IF(入力用!F23="✓","✓","□") -> □ | P13: 単位 | R13: 単位
C14: =IF(入力用!C21="","〔 〕",入力用!C21) -> 〔 〕 | D14: =IF(入力用!D21="","（ ）",入力用!D21) -> （ ） | E14: =IF(入力用!F21="✓","✓","□") -> □ | F14: =IF(入力用!C24="","〔 〕",入力用!C24) -> 〔 〕 | G14: =IF(入力用!D24="","（ ）",入力用!D24) -> （ ） | H14: =IF(入力用!F24="✓","✓","□") -> □ | I14: 単位 | J14: /8単位
B15: 理系 | C15: 情報科学 | D15: 2 | E15: =IF(入力用!F26="✓","✓","□") -> □ | F15: =IF(入力用!C30="","〔 〕",入力用!C30) -> 〔 〕 | G15: =IF(入力用!D30="","（ ）",入力用!D30) -> （ ） | H15: =IF(入力用!F30="✓","✓","□") -> □ | M15: 高年次基幹教育科目（必修：２単位）
C16: プログラミング演習 | D16: 1 | E16: =IF(入力用!F27="✓","✓","□") -> □ | F16: =IF(入力用!C31="","〔 〕",入力用!C31) -> 〔 〕 | G16: =IF(入力用!D31="","（ ）",入力用!D31) -> （ ） | H16: =IF(入力用!F31="✓","✓","□") -> □ | M16: =IF(入力用!C96="","〔 〕",入力用!C96) -> 〔 〕 | N16: =IF(入力用!D96="","（ ）",入力用!D96) -> （ ） | O16: =IF(入力用!F96="","□",入力用!F96) -> □ | P16: =IF(入力用!F97="","（ ）",入力用!F97) -> （ ）
C17: =IF(入力用!C28="","〔 〕",入力用!C28) -> 〔 〕 | D17: =IF(入力用!D28="","（ ）",入力用!D28) -> （ ） | E17: =IF(入力用!F28="✓","✓","□") -> □ | F17: =IF(入力用!C32="","〔 〕",入力用!C32) -> 〔 〕 | G17: =IF(入力用!D32="","（ ）",入力用!D32) -> （ ） | H17: =IF(入力用!F32="✓","✓","□") -> □ | M17: =IF(入力用!C97="","〔 〕",入力用!C97) -> 〔 〕 | N17: =IF(入力用!D97="","（ ）",入力用!D97) -> （ ） | O17: =IF(入力用!F96="","□",入力用!F96) -> □ | P17: =IF(入力用!F98="","（ ）",入力用!F98) -> （ ） | R17: 単位/2単位
C18: =IF(入力用!C29="","〔 〕",入力用!C29) -> 〔 〕 | D18: =IF(入力用!D29="","（ ）",入力用!D29) -> （ ） | E18: =IF(入力用!F29="✓","✓","□") -> □ | I18: 単位 | J18: /8単位 | M18: ※上記科目区分の必修単位を超えて修得した単位 | O18: その他(E） | Q18: その他(う）
B19: ※上記科目区分の必修単位を超えて修得した単位 | I19: その他（Ａ）計 | M19: =IF(入力用!C99="","〔 〕",入力用!C99) -> 〔 〕 | N19: =IF(入力用!D99="","（ ）",入力用!D99) -> （ ） | O19: =IF(入力用!G99="","□",入力用!G99) -> □ | P19: =IF(入力用!E102="","（ ）",入力用!E102) -> （ ） | Q19: =IF(入力用!H99="","□",入力用!H99) -> □ | R19: =IF(入力用!G102="","（ ）",入力用!G102) -> （ ）
B20: =IF(入力用!C34="","〔 〕",入力用!C34) -> 〔 〕 | D20: =IF(入力用!D34="","（ ）",入力用!D34) -> （ ） | E20: =IF(入力用!F34="✓","✓","□") -> □ | F20: =IF(入力用!C37="","〔 〕",入力用!C37) -> 〔 〕 | G20: =IF(入力用!D37="","（ ）",入力用!D37) -> （ ） | H20: =IF(入力用!F37="✓","✓","□") -> □ | M20: =IF(入力用!C100="","〔 〕",入力用!C100) -> 〔 〕 | N20: =IF(入力用!D100="","（ ）",入力用!D100) -> （ ） | O20: =IF(入力用!G100="","□",入力用!G100) -> □ | P20: =IF(入力用!E103="","（ ）",入力用!E103) -> （ ） | Q20: =IF(入力用!H100="","□",入力用!H100) -> □ | R20: =IF(入力用!G103="","（ ）",入力用!G103) -> （ ）
B21: =IF(入力用!C35="","〔 〕",入力用!C35) -> 〔 〕 | D21: =IF(入力用!D35="","（ ）",入力用!D35) -> （ ） | E21: =IF(入力用!F35="✓","✓","□") -> □ | F21: =IF(入力用!C38="","〔 〕",入力用!C38) -> 〔 〕 | G21: =IF(入力用!D38="","（ ）",入力用!D38) -> （ ） | H21: =IF(入力用!F38="✓","✓","□") -> □ | J21: 単位 | M21: =IF(入力用!C101="","〔 〕",入力用!C101) -> 〔 〕 | N21: =IF(入力用!D101="","（ ）",入力用!D101) -> （ ） | O21: =IF(入力用!G101="","□",入力用!G101) -> □ | P21: =IF(入力用!E105="","（ ）",入力用!E105) -> （ ） | Q21: =IF(入力用!H101="","□",入力用!H101) -> □ | R21: =IF(入力用!G105="","（ ）",入力用!G105) -> （ ）
B22: =IF(入力用!C36="","〔 〕",入力用!C36) -> 〔 〕 | D22: =IF(入力用!D36="","（ ）",入力用!D36) -> （ ） | E22: =IF(入力用!F36="✓","✓","□") -> □ | F22: =IF(入力用!C39="","〔 〕",入力用!C39) -> 〔 〕 | G22: =IF(入力用!D39="","（ ）",入力用!D39) -> （ ） | H22: =IF(入力用!F39="✓","✓","□") -> □ | M22: =IF(入力用!C102="","〔 〕",入力用!C102) -> 〔 〕 | N22: =IF(入力用!D102="","（ ）",入力用!D102) -> （ ） | O22: =IF(入力用!G102="","□",入力用!G102) -> □ | P22: =IF(入力用!E106="","（ ）",入力用!E106) -> （ ） | Q22: =IF(入力用!H102="","□",入力用!H102) -> □ | R22: =IF(入力用!G106="","（ ）",入力用!G106) -> その他（F）
M23: =IF(入力用!C103="","〔 〕",入力用!C103) -> 〔 〕 | N23: =IF(入力用!D103="","（ ）",入力用!D103) -> （ ） | O23: =IF(入力用!G103="","□",入力用!G103) -> □ | P23: =IF(入力用!E107="","（ ）",入力用!E107) -> （ ） | Q23: =IF(入力用!H103="","□",入力用!H103) -> □ | R23: =IF(入力用!G107="","（ ）",入力用!G107) -> （ ）
B24: 言語文化科目（必修：第１外国語１２単位，第２外国語４単位） | M24: =IF(入力用!C104="","〔 〕",入力用!C104) -> 〔 〕 | N24: =IF(入力用!D104="","（ ）",入力用!D104) -> （ ） | O24: =IF(入力用!G104="","□",入力用!G104) -> □ | P24: =IF(入力用!E108="","（ ）",入力用!E108) -> （ ） | Q24: =IF(入力用!H104="","□",入力用!H104) -> □ | R24: =IF(入力用!G108="","（ ）",入力用!G108) -> （ ）
B25: 第１外国語（英語） ※４月入学生 | M25: 合計 | O25: その他(E）計 | Q25: その他(う）計
B26: Intensive English: Global Issues RW 1 | D26: 1 | E26: =IF(入力用!F42="✓","✓","□") -> □ | F26: Intensive English: Academic Issues 2 | G26: 1 | H26: =IF(入力用!F47="✓","✓","□") -> □ | P26: 単位 | R26: 単位
B27: Intensive English: Global Issues LS 1 | D27: 1 | E27: =IF(入力用!F43="✓","✓","□") -> □ | F27: Intensive English: Japanese Issues 1 | G27: 1 | H27: =IF(入力用!F48="✓","✓","□") -> □
B28: Intensive English: Academic Issues 1 | D28: 1 | E28: =IF(入力用!F44="✓","✓","□") -> □ | F28: Intensive English: Academic Issues 3 | G28: 1 | H28: =IF(入力用!F49="✓","✓","□") -> □
B29: Intensive English: Global Issues RW 2 | D29: 1 | E29: =IF(入力用!F45="✓","✓","□") -> □ | F29: Intensive English: Japanese Issues 2 | G29: 1 | H29: =IF(入力用!F50="✓","✓","□") -> □ | M29: 他学部専攻教育科目 ※10単位まで卒業要件に含むことができる。
B30: Intensive English: Global Issues LS 2 | D30: 1 | E30: =IF(入力用!F46="✓","✓","□") -> □ | F30: Intensive English: Academic Issues 4 | G30: 1 | H30: =IF(入力用!F51="✓","✓","□") -> □ | I30: 単位 | J30: /10単位 | O30: その他(F） | Q30: その他(え）
B31: 学術英語（必修：２単位） | M31: =IF(入力用!C107="","〔 〕",入力用!C107) -> 〔 〕 | N31: =IF(入力用!D107="","（ ）",入力用!D107) -> （ ） | O31: =IF(入力用!G107="","□",入力用!G107) -> □ | P31: =IF(入力用!E115="","（ ）",入力用!E115) -> 最低修得単位数 | Q31: =IF(入力用!H107="","□",入力用!H107) -> □ | R31: =IF(入力用!G115="","（ ）",入力用!G115) -> その他 (基幹教育)
B32: =IF(入力用!C53="","〔 〕",入力用!C53) -> 〔 〕 | D32: =IF(入力用!D53="","（ ）",入力用!D53) -> （ ） | E32: =IF(入力用!F53="✓","✓","□") -> □ | F32: =IF(入力用!C54="","〔 〕",入力用!C54) -> 〔 〕 | G32: =IF(入力用!F54="","（ ）",入力用!F54) -> （ ） | H32: =IF(入力用!F54="✓","✓","□") -> □ | I32: 単位 | J32: /2単位 | M32: =IF(入力用!C108="","〔 〕",入力用!C108) -> 〔 〕 | N32: =IF(入力用!D108="","（ ）",入力用!D108) -> （ ） | O32: =IF(入力用!G108="","□",入力用!G108) -> □ | P32: =IF(入力用!E116="","（ ）",入力用!E116) -> 7 | Q32: =IF(入力用!H108="","□",入力用!H108) -> □ | R32: =IF(入力用!G116="","（ ）",入力用!G116) -> （ ）
B33: 第１外国語（日本語） ※10月入学生 | M33: =IF(入力用!C109="","〔 〕",入力用!C109) -> 〔 〕 | N33: =IF(入力用!D109="","（ ）",入力用!D109) -> （ ） | O33: =IF(入力用!G109="","□",入力用!G109) -> □ | P33: =IF(入力用!E117="","（ ）",入力用!E117) -> （ ） | Q33: =IF(入力用!H109="","□",入力用!H109) -> □ | R33: =IF(入力用!G117="","（ ）",入力用!G117) -> （ ）
B34: =IF(入力用!C56="","〔 〕",入力用!C56) -> 〔 〕 | D34: 1 | E34: =IF(入力用!F56="✓","✓","□") -> □ | F34: =IF(入力用!C62="","〔 〕",入力用!C62) -> 〔 〕 | G34: 1 | H34: =IF(入力用!F62="✓","✓","□") -> □ | M34: =IF(入力用!C110="","〔 〕",入力用!C110) -> 〔 〕 | N34: =IF(入力用!D110="","（ ）",入力用!D110) -> （ ） | O34: =IF(入力用!G110="","□",入力用!G110) -> □ | P34: =IF(入力用!E118="","（ ）",入力用!E118) -> （ ） | Q34: =IF(入力用!H110="","□",入力用!H110) -> □ | R34: =IF(入力用!G118="","（ ）",入力用!G118) -> （ ）
B35: =IF(入力用!C57="","〔 〕",入力用!C57) -> 〔 〕 | D35: 1 | E35: =IF(入力用!F57="✓","✓","□") -> □ | F35: =IF(入力用!C63="","〔 〕",入力用!C63) -> 〔 〕 | G35: 1 | H35: =IF(入力用!F63="✓","✓","□") -> □ | M35: =IF(入力用!C111="","〔 〕",入力用!C111) -> 〔 〕 | N35: =IF(入力用!D111="","（ ）",入力用!D111) -> （ ） | O35: =IF(入力用!G111="","□",入力用!G111) -> □ | P35: =IF(入力用!E119="","（ ）",入力用!E119) -> （ ） | Q35: =IF(入力用!H111="","□",入力用!H111) -> □ | R35: =IF(入力用!G119="","（ ）",入力用!G119) -> （ ）
B36: =IF(入力用!C58="","〔 〕",入力用!C58) -> 〔 〕 | D36: 1 | E36: =IF(入力用!F58="✓","✓","□") -> □ | F36: =IF(入力用!C64="","〔 〕",入力用!C64) -> 〔 〕 | G36: 1 | H36: =IF(入力用!F64="✓","✓","□") -> □ | M36: =IF(入力用!C112="","〔 〕",入力用!C112) -> 〔 〕 | N36: =IF(入力用!D112="","（ ）",入力用!D112) -> （ ） | O36: =IF(入力用!G112="","□",入力用!G112) -> □ | P36: =IF(入力用!E120="","（ ）",入力用!E120) -> （ ） | Q36: =IF(入力用!H112="","□",入力用!H112) -> □ | R36: =IF(入力用!G120="","（ ）",入力用!G120) -> （ ）
B37: =IF(入力用!C59="","〔 〕",入力用!C59) -> 〔 〕 | D37: 1 | E37: =IF(入力用!F59="✓","✓","□") -> □ | F37: =IF(入力用!C65="","〔 〕",入力用!C65) -> 〔 〕 | G37: 1 | H37: =IF(入力用!F65="✓","✓","□") -> □ | M37: 合計 | O37: その他(F）計 | Q37: その他(え）計
B38: =IF(入力用!C60="","〔 〕",入力用!C60) -> 〔 〕 | D38: 1 | E38: =IF(入力用!F60="✓","✓","□") -> □ | F38: =IF(入力用!C66="","〔 〕",入力用!C66) -> 〔 〕 | G38: 1 | H38: =IF(入力用!F66="✓","✓","□") -> □ | P38: 単位 | R38: 単位
B39: =IF(入力用!C61="","〔 〕",入力用!C61) -> 〔 〕 | D39: 1 | E39: =IF(入力用!F61="✓","✓","□") -> □ | F39: =IF(入力用!C67="","〔 〕",入力用!C67) -> 〔 〕 | G39: 1 | H39: =IF(入力用!F67="✓","✓","□") -> □ | I39: 単位 | J39: /12単位
B40: 第２外国語（必修：４単位） | D40: 選択言語 | F40: =IF(入力用!C7="","（ 語）",入力用!C7) -> （ 語）
...

Sheet 入力用
C1: に入力するとチェック表に反映されます
A3: 学生番号
A4: 氏名
A5: チェック日
A7: 第2外国語 （母語と第1外国語を除く）
A8: レクチャーシリーズのスタンプ数 （Moodleで確認すること）
A9: 「異文化対応２」に対する留学等の実施状況 （リストから選択）
A10: 留学の時期と期間（希望時期） | D10: （例：2024年夏休み（希望）、2025年4月～9月（確定）、具体的計画なし）
A11: 「異文化対応２」の履修予定時期（留学終了後で春夏秋冬学期のいずれか） | D11: （例：2025年秋学期）
A13: 卒業要件のチェック
A14: Ⅰ．基幹教育科目（48単位）
A15: 科目区分 | B15: 区分 | C15: 科目名 | D15: 単位数 | E15: 最低修得単位数 | F15: 修得したら「✓」 | G15: その他 (基幹教育) | H15: その他 (共創学部)
A16: 基幹教育セミナー | C16: 基幹教育セミナー | D16: 1 | E16: 1
A17: 課題教学科目 | C17: 課題教学科目 | D17: 2.5 | E17: 2.5
A18: 文系ディシプリン | E18: 8
B19: 1
B20: 2
B21: 3
B22: 4
B23: 5
B24: 6
A25: 理系ディシプリン | E25: 8
B26: 1 | C26: 情報科学 | D26: 2 | E26: 2
B27: 2 | C27: プログラミング演習 | D27: 1 | E27: 1
B28: 3
B29: 4
B30: 5
B31: 6
B32: 7
B33: 必修単位数を超えて修得した科目 | G33: その他（Ａ）
B34: 1
B35: 2
B36: 3
B37: 4
B38: 5
B39: 6
A40: 言語文化科目
B41: 第1外国語（英語）※4月入学生 | E41: 10
C42: Intensive English: Global Issues RW 1 | D42: 1 | E42: 1
C43: Intensive English: Global Issues LS 1 | D43: 1 | E43: 1
...

Sheet 変更不可
A1: ドイツ語 | B1: ✓ | C1: 実施済
A2: フランス語 | C2: 未実施、具体的計画あり（半年以内に出発）
A3: 中国語 | C3: 未実施、具体的計画あり（１年以内に出発）
A4: ロシア語 | C4: 未実施、具体的計画なし
A5: 韓国語
A6: スペイン語
A7: 英語
A8: 日本語

Sheet ★ISI (2023)
B1: Checklist for ISI Graduation Requirements（First Page） | L1: Students ID: | M1: =IF('For Data entry'!C3="","",'For Data entry'!C3)
B2: (For Students Enrolled 2023) | L2: Students Name: | M2: =IF('For Data entry'!C4="","",'For Data entry'!C4)
L3: Date Checked: | M3: =IF('For Data entry'!C5="","",'For Data entry'!C5)
B4: Ⅰ．KIKAN Education Courses (48 Credits) | G4: □＝Check Box (Check when you earn)
B5: KIKAN Education Seminar (Minimum Required Credits: 1) | M5: General Courses | O5: Others(Ｄ） | Q5: Others(い）
B6: KIKAN Education Seminar | G6: 1 | H6: =IF('For Data entry'!F17="✓","✓","□") -> □ | J6: 1 Credits | M6: =IF('For Data entry'!C89="","〔 〕",'For Data entry'!C89) -> 〔 〕 | N6: =IF('For Data entry'!D89="","（ ）",'For Data entry'!D89) -> （ ） | O6: =IF('For Data entry'!G89="","□",'For Data entry'!G89) -> □ | P6: =IF(入力用!E89="","（ ）",入力用!E89) -> （ ） | Q6: =IF('For Data entry'!H89="","□",'For Data entry'!H89) -> □ | R6: =IF(入力用!G89="","（ ）",入力用!G89) -> （ ）
M7: =IF('For Data entry'!C90="","〔 〕",'For Data entry'!C90) -> 〔 〕 | N7: =IF('For Data entry'!D90="","（ ）",'For Data entry'!D90) -> （ ） | O7: =IF('For Data entry'!G90="","□",'For Data entry'!G90) -> □ | P7: =IF(入力用!E90="","（ ）",入力用!E90) -> （ ） | Q7: =IF('For Data entry'!H90="","□",'For Data entry'!H90) -> □ | R7: =IF(入力用!G90="","（ ）",入力用!G90) -> （ ）
B8: Interdisciplinary Collaborative Learning of Social Isues (Minimum Required Credits: 2.5) | M8: =IF('For Data entry'!C91="","〔 〕",'For Data entry'!C91) -> 〔 〕 | N8: =IF('For Data entry'!D91="","（ ）",'For Data entry'!D91) -> （ ） | O8: =IF('For Data entry'!G91="","□",'For Data entry'!G91) -> □ | P8: =IF(入力用!E91="","（ ）",入力用!E91) -> （ ） | Q8: =IF('For Data entry'!H91="","□",'For Data entry'!H91) -> □ | R8: =IF(入力用!G91="","（ ）",入力用!G91) -> （ ）
B9: Interdisciplinary Collaborative Learning of Social Isues | G9: 2.5 | H9: =IF('For Data entry'!F18="✓","✓","□") -> □ | J9: 2.5 Credits | M9: =IF('For Data entry'!C92="","〔 〕",'For Data entry'!C92) -> 〔 〕 | N9: =IF('For Data entry'!D92="","（ ）",'For Data entry'!D92) -> （ ） | O9: =IF('For Data entry'!G92="","□",'For Data entry'!G92) -> □ | P9: =IF(入力用!E92="","（ ）",入力用!E92) -> （ ） | Q9: =IF('For Data entry'!H92="","□",'For Data entry'!H92) -> □ | R9: =IF(入力用!G92="","（ ）",入力用!G92) -> （ ）
M10: =IF('For Data entry'!C93="","〔 〕",'For Data entry'!C93) -> 〔 〕 | N10: =IF('For Data entry'!D93="","（ ）",'For Data entry'!D93) -> （ ） | O10: =IF('For Data entry'!G93="","□",'For Data entry'!G93) -> □ | P10: =IF(入力用!E93="","（ ）",入力用!E93) -> （ ） | Q10: =IF('For Data entry'!H93="","□",'For Data entry'!H93) -> □ | R10: =IF(入力用!G93="","（ ）",入力用!G93) -> （ ）
B11: Courses in Humanities and Social Sciences and Courses in Science (each Minimum Required Credits: 8) | M11: =IF('For Data entry'!C94="","〔 〕",'For Data entry'!C94) -> 〔 〕 | N11: =IF('For Data entry'!D94="","（ ）",'For Data entry'!D94) -> （ ） | O11: =IF('For Data entry'!G94="","□",'For Data entry'!G94) -> □ | P11: =IF(入力用!E94="","（ ）",入力用!E94) -> （ ） | Q11: =IF('For Data entry'!H94="","□",'For Data entry'!H94) -> □ | R11: =IF(入力用!G94="","（ ）",入力用!G94) -> （ ）
C12: =IF('For Data entry'!C20="","〔 〕",'For Data entry'!C20) -> 〔 〕 | D12: =IF('For Data entry'!D20="","（ ）",'For Data entry'!D20) -> （ ） | E12: =IF('For Data entry'!F20="✓","✓","□") -> □ | F12: =IF('For Data entry'!C23="","〔 〕",'For Data entry'!C23) -> 〔 〕 | G12: =IF('For Data entry'!D23="","（ ）",'For Data entry'!D23) -> （ ） | H12: =IF('For Data entry'!F23="✓","✓","□") -> □ | O12: Others(Ｄ） | Q12: Others(い）
C13: =IF('For Data entry'!C21="","〔 〕",'For Data entry'!C21) -> 〔 〕 | D13: =IF('For Data entry'!D21="","（ ）",'For Data entry'!D21) -> （ ） | E13: =IF('For Data entry'!F21="✓","✓","□") -> □ | F13: =IF('For Data entry'!C24="","〔 〕",'For Data entry'!C24) -> 〔 〕 | G13: =IF('For Data entry'!D24="","（ ）",'For Data entry'!D24) -> （ ） | H13: =IF('For Data entry'!F24="✓","✓","□") -> □ | P13: Credits | R13: Credits
C14: =IF('For Data entry'!C22="","〔 〕",'For Data entry'!C22) -> 〔 〕 | D14: =IF('For Data entry'!D22="","（ ）",'For Data entry'!D22) -> （ ） | E14: =IF('For Data entry'!F22="✓","✓","□") -> □ | F14: =IF('For Data entry'!C25="","〔 〕",'For Data entry'!C25) -> 〔 〕 | G14: =IF('For Data entry'!D25="","（ ）",'For Data entry'!D25) -> （ ） | H14: =IF('For Data entry'!F25="✓","✓","□") -> □ | I14: Credits | J14: /8 Credits | M14: KIKAN Education Courses for students in the 2nd year and above
B15: Science | C15: Information Science | D15: 2 | E15: =IF('For Data entry'!F27="✓","✓","□") -> □ | F15: =IF('For Data entry'!C31="","〔 〕",'For Data entry'!C31) -> 〔 〕 | G15: =IF('For Data entry'!D31="","（ ）",'For Data entry'!D31) -> （ ） | H15: =IF('For Data entry'!F31="✓","✓","□") -> □ | M15: (Minimum Required Credits: 2)
C16: Computer Programming Excercise | D16: 1 | E16: =IF('For Data entry'!F28="✓","✓","□") -> □ | F16: =IF('For Data entry'!C32="","〔 〕",'For Data entry'!C32) -> 〔 〕 | G16: =IF('For Data entry'!D32="","（ ）",'For Data entry'!D32) -> （ ） | H16: =IF('For Data entry'!F32="✓","✓","□") -> □ | M16: =IF('For Data entry'!C96="","〔 〕",'For Data entry'!C96) -> 〔 〕 | N16: =IF('For Data entry'!D96="","（ ）",'For Data entry'!D96) -> （ ） | O16: =IF('For Data entry'!F96="","□",'For Data entry'!F96) -> □ | P16: =IF(入力用!F97="","（ ）",入力用!F97) -> （ ）
C17: =IF('For Data entry'!C29="","〔 〕",'For Data entry'!C29) -> 〔 〕 | D17: =IF('For Data entry'!D29="","（ ）",'For Data entry'!D29) -> （ ） | E17: =IF('For Data entry'!F29="✓","✓","□") -> □ | F17: =IF('For Data entry'!C33="","〔 〕",'For Data entry'!C33) -> 〔 〕 | G17: =IF('For Data entry'!D33="","（ ）",'For Data entry'!D33) -> （ ） | H17: =IF('For Data entry'!F33="✓","✓","□") -> □ | M17: =IF('For Data entry'!C97="","〔 〕",'For Data entry'!C97) -> 〔 〕 | N17: =IF('For Data entry'!D97="","（ ）",'For Data entry'!D97) -> （ ） | O17: =IF('For Data entry'!F97="","□",'For Data entry'!F97) -> □ | P17: =IF(入力用!F98="","（ ）",入力用!F98) -> （ ） | Q17: Credits | R17: /2 Credits
C18: =IF('For Data entry'!C30="","〔 〕",'For Data entry'!C30) -> 〔 〕 | D18: =IF('For Data entry'!D30="","（ ）",'For Data entry'!D30) -> （ ） | E18: =IF('For Data entry'!F30="✓","✓","□") -> □ | I18: Credits | J18: /8 Credits | M18: ※Earned credits in excess of minimum required credits | O18: Others(E） | Q18: Others(う）
B19: ※Earned credits in excess of minimum required credits in above category | I19: Others（Ａ） | M19: =IF('For Data entry'!C99="","〔 〕",'For Data entry'!C99) -> 〔 〕 | N19: =IF('For Data entry'!D99="","（ ）",'For Data entry'!D99) -> （ ） | O19: =IF('For Data entry'!G99="","□",'For Data entry'!G99) -> □ | P19: =IF(入力用!E102="","（ ）",入力用!E102) -> （ ） | Q19: =IF('For Data entry'!H99="","□",'For Data entry'!H99) -> □ | R19: =IF(入力用!G102="","（ ）",入力用!G102) -> （ ）
B20: =IF('For Data entry'!C35="","〔 〕",'For Data entry'!C35) -> 〔 〕 | D20: =IF('For Data entry'!D35="","（ ）",'For Data entry'!D35) -> （ ） | E20: =IF('For Data entry'!F35="✓","✓","□") -> □ | F20: =IF('For Data entry'!C38="","〔 〕",'For Data entry'!C38) -> 〔 〕 | G20: =IF('For Data entry'!D38="","（ ）",'For Data entry'!D38) -> （ ） | H20: =IF('For Data entry'!F38="✓","✓","□") -> □ | M20: =IF('For Data entry'!C100="","〔 〕",'For Data entry'!C100) -> 〔 〕 | N20: =IF('For Data entry'!D100="","（ ）",'For Data entry'!D100) -> （ ） | O20: =IF('For Data entry'!G100="","□",'For Data entry'!G100) -> □ | P20: =IF(入力用!E103="","（ ）",入力用!E103) -> （ ） | Q20: =IF('For Data entry'!H100="","□",'For Data entry'!H100) -> □ | R20: =IF(入力用!G103="","（ ）",入力用!G103) -> （ ）
B21: =IF('For Data entry'!C36="","〔 〕",'For Data entry'!C36) -> 〔 〕 | D21: =IF('For Data entry'!D36="","（ ）",'For Data entry'!D36) -> （ ） | E21: =IF('For Data entry'!F36="✓","✓","□") -> □ | F21: =IF('For Data entry'!C39="","〔 〕",'For Data entry'!C39) -> 〔 〕 | G21: =IF('For Data entry'!D39="","（ ）",'For Data entry'!D39) -> （ ） | H21: =IF('For Data entry'!F39="✓","✓","□") -> □ | J21: Credits | M21: =IF('For Data entry'!C101="","〔 〕",'For Data entry'!C101) -> 〔 〕 | N21: =IF('For Data entry'!D101="","（ ）",'For Data entry'!D101) -> （ ） | O21: =IF('For Data entry'!G101="","□",'For Data entry'!G101) -> □ | P21: =IF(入力用!E105="","（ ）",入力用!E105) -> （ ） | Q21: =IF('For Data entry'!H101="","□",'For Data entry'!H101) -> □ | R21: =IF(入力用!G105="","（ ）",入力用!G105) -> （ ）
B22: =IF('For Data entry'!C37="","〔 〕",'For Data entry'!C37) -> 〔 〕 | D22: =IF('For Data entry'!D37="","（ ）",'For Data entry'!D37) -> （ ） | E22: =IF('For Data entry'!F37="✓","✓","□") -> □ | F22: =IF('For Data entry'!C40="","〔 〕",'For Data entry'!C40) -> 〔 〕 | G22: =IF('For Data entry'!D40="","（ ）",'For Data entry'!D40) -> （ ） | H22: =IF('For Data entry'!F40="✓","✓","□") -> □ | M22: =IF('For Data entry'!C102="","〔 〕",'For Data entry'!C102) -> 〔 〕 | N22: =IF('For Data entry'!D102="","（ ）",'For Data entry'!D102) -> （ ） | O22: =IF('For Data entry'!G102="","□",'For Data entry'!G102) -> □ | P22: =IF(入力用!E106="","（ ）",入力用!E106) -> （ ） | Q22: =IF('For Data entry'!H102="","□",'For Data entry'!H102) -> □ | R22: =IF(入力用!G106="","（ ）",入力用!G106) -> その他（F）
M23: =IF('For Data entry'!C103="","〔 〕",'For Data entry'!C103) -> 〔 〕 | N23: =IF('For Data entry'!D103="","（ ）",'For Data entry'!D103) -> （ ） | O23: =IF('For Data entry'!G103="","□",'For Data entry'!G103) -> □ | P23: =IF(入力用!E107="","（ ）",入力用!E107) -> （ ） | Q23: =IF('For Data entry'!H103="","□",'For Data entry'!H103) -> □ | R23: =IF(入力用!G107="","（ ）",入力用!G107) -> （ ）
B24: Courses for Language and Cultures (Minimum Required Credits: First Language 12, Second Language 4) | M24: =IF('For Data entry'!C104="","〔 〕",'For Data entry'!C104) -> 〔 〕 | N24: =IF('For Data entry'!D104="","（ ）",'For Data entry'!D104) -> （ ） | O24: =IF('For Data entry'!G104="","□",'For Data entry'!G104) -> □ | P24: =IF(入力用!E108="","（ ）",入力用!E108) -> （ ） | Q24: =IF('For Data entry'!H104="","□",'For Data entry'!H104) -> □ | R24: =IF(入力用!G108="","（ ）",入力用!G108) -> （ ）
B25: First Foreign Language (English) ※Students enrolled in April only | O25: Others(E） | Q25: Others(う）
B26: Intensive English: Global Issues RW 1 | D26: 1 | E26: =IF('For Data entry'!F43="✓","✓","□") -> □ | F26: Intensive English: Academic Issues 2 | G26: 1 | H26: =IF('For Data entry'!F48="✓","✓","□") -> □ | P26: Credits | R26: Credits
B27: Intensive English: Global Issues LS 1 | D27: 1 | E27: =IF('For Data entry'!F44="✓","✓","□") -> □ | F27: Intensive English: Japanese Issues 1 | G27: 1 | H27: =IF('For Data entry'!F49="✓","✓","□") -> □
B28: Intensive English: Academic Issues 1 | D28: 1 | E28: =IF('For Data entry'!F45="✓","✓","□") -> □ | F28: Intensive English: Academic Issues 3 | G28: 1 | H28: =IF('For Data entry'!F50="✓","✓","□") -> □
B29: Intensive English: Global Issues RW 2 | D29: 1 | E29: =IF('For Data entry'!F46="✓","✓","□") -> □ | F29: Intensive English: Japanese Issues 2 | G29: 1 | H29: =IF('For Data entry'!F51="✓","✓","□") -> □ | M29: Specialized Courses of other departments ※Up to 10 Credits
B30: Intensive English: Global Issues LS 2 | D30: 1 | E30: =IF('For Data entry'!F47="✓","✓","□") -> □ | F30: Intensive English: Academic Issues 4 | G30: 1 | H30: =IF('For Data entry'!F52="✓","✓","□") -> □ | I30: Credits | J30: /10 Credits | O30: Others(F） | Q30: Others(え）
B31: Academic English (Minimum Required Credits: 2) | M31: =IF('For Data entry'!C107="","〔 〕",'For Data entry'!C107) -> 〔 〕 | N31: =IF('For Data entry'!D107="","（ ）",'For Data entry'!D107) -> （ ） | O31: =IF('For Data entry'!G107="","□",'For Data entry'!G107) -> □ | P31: =IF(入力用!E115="","（ ）",入力用!E115) -> 最低修得単位数 | Q31: =IF('For Data entry'!H107="","□",'For Data entry'!H107) -> □ | R31: =IF(入力用!G115="","（ ）",入力用!G115) -> その他 (基幹教育)
B32: =IF('For Data entry'!C54="","〔 〕",'For Data entry'!C54) -> 〔 〕 | D32: =IF('For Data entry'!D54="","（ ）",'For Data entry'!D54) -> （ ） | E32: =IF('For Data entry'!F54="✓","✓","□") -> □ | F32: =IF('For Data entry'!C55="","〔 〕",'For Data entry'!C55) -> 〔 〕 | G32: =IF('For Data entry'!D55="","（ ）",'For Data entry'!D55) -> （ ） | H32: =IF('For Data entry'!F55="✓","✓","□") -> □ | I32: Credits | J32: /2 Credits | M32: =IF('For Data entry'!C108="","〔 〕",'For Data entry'!C108) -> 〔 〕 | N32: =IF('For Data entry'!D108="","（ ）",'For Data entry'!D108) -> （ ） | O32: =IF('For Data entry'!G108="","□",'For Data entry'!G108) -> □ | P32: =IF(入力用!E116="","（ ）",入力用!E116) -> 7 | Q32: =IF('For Data entry'!H108="","□",'For Data entry'!H108) -> □ | R32: =IF(入力用!G116="","（ ）",入力用!G116) -> （ ）
B33: First Foreign Language (Japanese) ※Students enrolled in October only | M33: =IF('For Data entry'!C109="","〔 〕",'For Data entry'!C109) -> 〔 〕 | N33: =IF('For Data entry'!D109="","（ ）",'For Data entry'!D109) -> （ ） | O33: =IF('For Data entry'!G109="","□",'For Data entry'!G109) -> □ | P33: =IF(入力用!E117="","（ ）",入力用!E117) -> （ ） | Q33: =IF('For Data entry'!H109="","□",'For Data entry'!H109) -> □ | R33: =IF(入力用!G117="","（ ）",入力用!G117) -> （ ）
B34: =IF('For Data entry'!C57="","〔 〕",'For Data entry'!C57) -> 〔 〕 | D34: 1 | E34: =IF('For Data entry'!F57="✓","✓","□") -> □ | F34: =IF('For Data entry'!C63="","〔 〕",'For Data entry'!C63) -> 〔 〕 | G34: 1 | H34: =IF('For Data entry'!F63="✓","✓","□") -> □ | M34: =IF('For Data entry'!C110="","〔 〕",'For Data entry'!C110) -> 〔 〕 | N34: =IF('For Data entry'!D110="","（ ）",'For Data entry'!D110) -> （ ） | O34: =IF('For Data entry'!G110="","□",'For Data entry'!G110) -> □ | P34: =IF(入力用!E118="","（ ）",入力用!E118) -> （ ） | Q34: =IF('For Data entry'!H110="","□",'For Data entry'!H110) -> □ | R34: =IF(入力用!G118="","（ ）",入力用!G118) -> （ ）
B35: =IF('For Data entry'!C58="","〔 〕",'For Data entry'!C58) -> 〔 〕 | D35: 1 | E35: =IF('For Data entry'!F58="✓","✓","□") -> □ | F35: =IF('For Data entry'!C64="","〔 〕",'For Data entry'!C64) -> 〔 〕 | G35: 1 | H35: =IF('For Data entry'!F64="✓","✓","□") -> □ | M35: =IF('For Data entry'!C111="","〔 〕",'For Data entry'!C111) -> 〔 〕 | N35: =IF('For Data entry'!D111="","（ ）",'For Data entry'!D111) -> （ ） | O35: =IF('For Data entry'!G111="","□",'For Data entry'!G111) -> □ | P35: =IF(入力用!E119="","（ ）",入力用!E119) -> （ ） | Q35: =IF('For Data entry'!H111="","□",'For Data entry'!H111) -> □ | R35: =IF(入力用!G119="","（ ）",入力用!G119) -> （ ）
B36: =IF('For Data entry'!C59="","〔 〕",'For Data entry'!C59) -> 〔 〕 | D36: 1 | E36: =IF('For Data entry'!F59="✓","✓","□") -> □ | F36: =IF('For Data entry'!C65="","〔 〕",'For Data entry'!C65) -> 〔 〕 | G36: 1 | H36: =IF('For Data entry'!F65="✓","✓","□") -> □ | M36: =IF('For Data entry'!C112="","〔 〕",'For Data entry'!C112) -> 〔 〕 | N36: =IF('For Data entry'!D112="","（ ）",'For Data entry'!D112) -> （ ） | O36: =IF('For Data entry'!G112="","□",'For Data entry'!G112) -> □ | P36: =IF(入力用!E120="","（ ）",入力用!E120) -> （ ） | Q36: =IF('For Data entry'!H112="","□",'For Data entry'!H112) -> □ | R36: =IF(入力用!G120="","（ ）",入力用!G120) -> （ ）
B37: =IF('For Data entry'!C60="","〔 〕",'For Data entry'!C60) -> 〔 〕 | D37: 1 | E37: =IF('For Data entry'!F60="✓","✓","□") -> □ | F37: =IF('For Data entry'!C66="","〔 〕",'For Data entry'!C66) -> 〔 〕 | G37: 1 | H37: =IF('For Data entry'!F66="✓","✓","□") -> □ | O37: Others(F） | Q37: Others(え）
B38: =IF('For Data entry'!C61="","〔 〕",'For Data entry'!C61) -> 〔 〕 | D38: 1 | E38: =IF('For Data entry'!F61="✓","✓","□") -> □ | F38: =IF('For Data entry'!C67="","〔 〕",'For Data entry'!C67) -> 〔 〕 | G38: 1 | H38: =IF('For Data entry'!F67="✓","✓","□") -> □ | P38: Credits | R38: Credits
B39: =IF('For Data entry'!C62="","〔 〕",'For Data entry'!C62) -> 〔 〕 | D39: 1 | E39: =IF('For Data entry'!F62="✓","✓","□") -> □ | F39: =IF('For Data entry'!C68="","〔 〕",'For Data entry'!C68) -> 〔 〕 | G39: 1 | H39: =IF('For Data entry'!F68="✓","✓","□") -> □ | I39: Credits | J39: /12 Credits
B40: Second Foreign Language (Minimum Required Credits: 4) Selected Second Language : | I40: =IF('For Data entry'!C7="","（ ）",'For Data entry'!C7) -> （ ） | J40: =IF(入力用!G7="","（ 語）",入力用!G7) -> （ 語）
...

Sheet For Data entry
C1: Input data will emaerge the Check List
A3: Student ID
A4: Name
A5: Checking Date
A7: Second Foreign Language (You cannot select the first foreign language nor your main native language) | D7: (Choose from the list)
A8: Your main native language
A9: Number of stamps earned to date of Lecture Series (Refer to Moodle)
A10: Progress of International Experience (Study abroad/ Internship) for "Cross-Cultural Adjustment 2" | D10: (Choose from the list)
A11: Timing and duration schedule for international experience | D11: (e.g. 2024 Summer(estimated), Jun. to Feb. in 2025(confirmed), no particular plan)
A12: When to take "Cross-Cultural Adjustment 2" after International Experience(e.g. Spring quarter in 2025) | D12: (e.g. Spring Quarter in 2025)
A14: Check for the required credits for graduation
A15: Ⅰ．KIKAN Education Courses (48 Credits)
A16: Category | C16: Courses | D16: No. of credits | E16: Minimum acquired credits | F16: Choose「✓」after you acquired credit | G16: Others for KIKAN education | H16: Others for ISI Courses
A17: KIKAN Education Seminars | C17: KIKAN Education Seminars | D17: 1 | E17: 1
A18: Interdisciplinary Collaborative Learning of Social Issues | C18: Interdisciplinary Collaborative Learning of Social Issues | D18: 2.5 | E18: 2.5
A19: Courses in Humanities and Social Sciences | E19: 8
B20: 1
B21: 2
B22: 3
B23: 4
B24: 5
B25: 6
A26: Courses in Science | E26: 8
B27: 1 | C27: Information Science | D27: 2 | E27: 2
B28: 2 | C28: Computer Programming Exercise | D28: 1 | E28: 1
B29: 3
B30: 4
B31: 5
B32: 6
B33: 7
B34: Earned credits in excess of minimum required credits in above category | G34: Others（Ａ）
B35: 1
B36: 2
B37: 3
B38: 4
B39: 5
B40: 6
A41: Courses for languages and Cultures
B42: First Foreign Language (English) *April Enrolled Students only | E42: 10
C43: Intensive English: Global Issues RW 1 | D43: 1 | E43: 1
...

Sheet Do not Change
A1: German | B1: ✓ | C1: already finished International Experience for "Cross-Cultural Adjustment".
A2: French | C2: not finished yet, but specifically plan for next six months
A3: Chinese | C3: not finished yet, but specifically plan for next year
A4: Russian | C4: not finished yet and no plans
A5: Korean
A6: Spanish
A7: English
A8: Japanese
